Workbook

Sheet README
A1: Lead Scoring Phase 0 Workbook (DUMMY DATA)
A3: All leads, names, emails and companies in this file are synthetic. Built to rehearse the Phase 0 audit before real data is available.
A5: Tabs
A6: Leads | 800 synthetic leads, Oct 2025 to Sep 2026, with rule-based spam flags calculated by formula (columns R to X).
A7: Audit | Phase 0 baselines. Volume, spam share, logging gaps, qualification rates, response times. All formulas.
A8: Spam Rules | Draft v0 spam rules with hits, precision and recall against tagged leads. Edit keywords or threshold to test.
A9: Label Sample | 150 leads for manual labeling practice. Pick a label from the dropdown in column H.
A10: Answer Key | The hidden true label for each sample lead, to check manual labeling accuracy.
A12: Status values
A13: Spam, Unqualified, Open (in progress), Qualified (opportunity), Won, Lost (qualified then lost). Blank = never tagged.
A14: Qualified+ = Qualified + Won + Lost, i.e. the lead reached qualified opportunity (the proposed primary label).
A16: Legend
... A20: Conversion Model | Phase 3 learned weights, live probability in Leads column AG, test results and calibration check.

Sheet Leads
A1: Lead ID | B1: Created At | C1: Source | D1: Name | E1: Email | F1: Email Type | G1: Company | H1: Website | I1: Country | J1: Product Interest | K1: Form Message | L1: Pages Visited | M1: First Response (hrs) | N1: Owner | O1: Status | P1: Deal Value (USD) | Q1: Flag: Disposable Email | R1: Flag: Vendor/Scam Keyword | S1: Flag: Free Email + No Company | T1: Flag: Very Short Message | U1: Flag: Duplicate Email | V1: Rule Score | W1: Rule Verdict | X1: Pts: Source | Y1: Pts: Email Type | Z1: Pts: Product | AA1: Pts: Engagement | AB1: Pts: Buying Intent | AC1: Pts: Negative Intent | AD1: Lead Score | AE1: Bucket | AF1: Top Reasons | AG1: Conversion Probability | AH1: Resolved Outcome (1 = Qualified+, 0 = Unqualified)
A2: L-0001 | B2: 45931.656 | C2: Website Contact Form | D2: Mateo Ivanova | E2: mateo.ivanova@freemail.example | F2: Free | G2: Quillmoor Money | I2: UAE | J2: Payments - Virtual Accounts | K2: We raised a seed round and plan to launch a digital savings platform for SMEs. Want to discuss infrastructure. | L2: 3 | M2: 26 | N2: Vikram | Q2: =IF(F2="Disposable",1,0) -> 0 | R2: =IF(SUMPRODUCT(--ISNUMBER(SEARCH('Spam Rules'!$A$22:$A$35,K2)))>0,1,0) -> 0 | S2: =IF(AND(F2="Free",G2=""),1,0) -> 0 | T2: =IF(LEN(TRIM(K2))<15,1,0) -> 0 | U2: =IF(COUNTIF($E$2:$E$801,E2)>1,1,0) -> 0 | V2: =Q2*'Spam Rules'!$H$6+R2*'Spam Rules'!$H$7+S2*'Spam Rules'!$H$8+T2*'Spam Rules'!$H$9+U2*'Spam Rules'!$H$10 -> 0 | W2: =IF(V2>='Spam Rules'!$B$3,"Likely Spam","Genuine") -> Genuine | X2: =IFERROR(INDEX('Scoring Model'!$B$5:$B$11,MATCH(C2,'Scoring Model'!$A$5:$A$11,0)),0) -> 10 | Y2: =IFERROR(INDEX('Scoring Model'!$E$5:$E$7,MATCH(F2,'Scoring Model'!$D$5:$D$7,0)),0) -> 0 | Z2: =IFERROR(INDEX('Scoring Model'!$H$5:$H$13,MATCH(J2,'Scoring Model'!$G$5:$G$13,0)),0) -> 15 | AA2: =IF(L2>='Scoring Model'!$B$14,'Scoring Model'!$B$15,IF(L2>='Scoring Model'!$B$16,'Scoring Model'!$B$17,0)) -> 0 | AB2: =IF(SUMPRODUCT(--ISNUMBER(SEARCH('Scoring Model'!$D$16:$D$25,K2)))>0,'Scoring Model'!$B$18,0) -> 15 | AC2: =IF(SUMPRODUCT(--ISNUMBER(SEARCH('Scoring Model'!$G$16:$G$23,K2)))>0,'Scoring Model'!$B$19,0) -> 0 | AD2: =IF(W2="Likely Spam","",SUM(X2:AC2)) -> 40 | AE2: =IF(W2="Likely Spam","Spam",IF(AD2>='Scoring Model'!$B$21,"Hot",IF(AD2>='Scoring Model'!$B$22,"Warm","Nurture"))) -> Nurture | AF2: =IF(W2="Likely Spam","Flagged by spam rules",TRIM(IF(X2>=20,"Strong source. ","")&IF(Y2>0,"Company email. ","")&IF(Z2>=15,"High-value product. ","")&IF(AA2>='Scoring Model'!$B$15,"High engagement. ","")&IF(AB2>0,"Buying intent in message. ","")&IF(AC2<0,"Negative intent in message. ",""))) -> High-value product. Buying intent in message. | AG2: =IF(W2="Likely Spam","",1/(1+EXP(-('Conversion Model'!$B$5+IFERROR(INDEX('Conversion Model'!$B$8:$B$14,MATCH(C2,'Conversion Model'!$A$8:$A$14,0)),0)+IFERROR(INDEX('Conversion Model'!$E$8:$E$9,MATCH(F2,'Conversion Model'!$D$8:$D$9,0)),0)+IFERROR(INDEX('Conversion Model'!$H$8:$H$12,MATCH(IF(LEFT(J2,8)="Payments","Payments",IF(LEFT(J2,7)="Lending","Lending",J2)),'Conversion Model'!$G$8:$G$12,0)),0)+MIN(L2,15)*'Conversion Model'!$B$17+IF(SUMPRODUCT(--ISNUMBER(SEARCH('Scoring Model'!$D$16:$D$25,K2)))>0,'Conversion Model'!$B$18,0)+IF(SUMPRODUCT(--ISNUMBER(SEARCH('Scoring Model'!$G$16:$G$23,K2)))>0,'Conversion Model'!$B$19,0))))) -> 0.15446527 | AH2: =IF(OR(O2="Qualified",O2="Won",O2="Lost"),1,IF(O2="Unqualified",0,""))
A3: L-0002 | B3: 45931.767 | C3: Website Contact Form | D3: Elena Berg | E3: elena60@vanishmail.example | F3: Disposable | I3: UK | J3: Other | K3: Boost your Twitter followers and Telegram members, organic fintech marketing. | L3: 1 | N3: Unassigned | O3: Spam | Q3: =IF(F3="Disposable",1,0) -> 1 | R3: =IF(SUMPRODUCT(--ISNUMBER(SEARCH('Spam Rules'!$A$22:$A$35,K3)))>0,1,0) -> 1 | S3: =IF(AND(F3="Free",G3=""),1,0) -> 0 | T3: =IF(LEN(TRIM(K3))<15,1,0) -> 0 | U3: =IF(COUNTIF($E$2:$E$801,E3)>1,1,0) -> 1 | V3: =Q3*'Spam Rules'!$H$6+R3*'Spam Rules'!$H$7+S3*'Spam Rules'!$H$8+T3*'Spam Rules'!$H$9+U3*'Spam Rules'!$H$10 -> 2 | W3: =IF(V3>='Spam Rules'!$B$3,"Likely Spam","Genuine") -> Likely Spam | X3: =IFERROR(INDEX('Scoring Model'!$B$5:$B$11,MATCH(C3,'Scoring Model'!$A$5:$A$11,0)),0) -> 10 | Y3: =IFERROR(INDEX('Scoring Model'!$E$5:$E$7,MATCH(F3,'Scoring Model'!$D$5:$D$7,0)),0) -> 0 | Z3: =IFERROR(INDEX('Scoring Model'!$H$5:$H$13,MATCH(J3,'Scoring Model'!$G$5:$G$13,0)),0) -> 0 | AA3: =IF(L3>='Scoring Model'!$B$14,'Scoring Model'!$B$15,IF(L3>='Scoring Model'!$B$16,'Scoring Model'!$B$17,0)) -> 0 | AB3: =IF(SUMPRODUCT(--ISNUMBER(SEARCH('Scoring Model'!$D$16:$D$25,K3)))>0,'Scoring Model'!$B$18,0) -> 0 | AC3: =IF(SUMPRODUCT(--ISNUMBER(SEARCH('Scoring Model'!$G$16:$G$23,K3)))>0,'Scoring Model'!$B$19,0) -> 0 | AD3: =IF(W3="Likely Spam","",SUM(X3:AC3)) | AE3: =IF(W3="Likely Spam","Spam",IF(AD3>='Scoring Model'!$B$21,"Hot",IF(AD3>='Scoring Model'!$B$22,"Warm","Nurture"))) -> Spam | AF3: =IF(W3="Likely Spam","Flagged by spam rules",TRIM(IF(X3>=20,"Strong source. ","")&IF(Y3>0,"Company email. ","")&IF(Z3>=15,"High-value product. ","")&IF(AA3>='Scoring Model'!$B$15,"High engagement. ","")&IF(AB3>0,"Buying intent in message. ","")&IF(AC3<0,"Negative intent in message. ",""))) -> Flagged by spam rules | AG3: =IF(W3="Likely Spam","",1/(1+EXP(-('Conversion Model'!$B$5+IFERROR(INDEX('Conversion Model'!$B$8:$B$14,MATCH(C3,'Conversion Model'!$A$8:$A$14,0)),0)+IFERROR(INDEX('Conversion Model'!$E$8:$E$9,MATCH(F3,'Conversion Model'!$D$8:$D$9,0)),0)+IFERROR(INDEX('Conversion Model'!$H$8:$H$12,MATCH(IF(LEFT(J3,8)="Payments","Payments",IF(LEFT(J3,7)="Lending","Lending",J3)),'Conversion Model'!$G$8:$G$12,0)),0)+MIN(L3,15)*'Conversion Model'!$B$17+IF(SUMPRODUCT(--ISNUMBER(SEARCH('Scoring Model'!$D$16:$D$25,K3)))>0,'Conversion Model'!$B$18,0)+IF(SUMPRODUCT(--ISNUMBER(SEARCH('Scoring Model'!$G$16:$G$23,K3)))>0,'Conversion Model'!$B$19,0))))) | AH3: =IF(OR(O3="Qualified",O3="Won",O3="Lost"),1,IF(O3="Unqualified",0,""))
A4: L-0003 | B4: 45931.926 | C4: Website Contact Form | D4: Daniel Brown | E4: daniel.brown@webmail.example | F4: Free | G4: Plumeridge Money | I4: Switzerland | J4: Other | K4: I am a student researching open banking for my thesis. Can you share some material? | L4: 2 | M4: 1.5 | N4: Vikram | Q4: =IF(F4="Disposable",1,0) -> 0 | R4: =IF(SUMPRODUCT(--ISNUMBER(SEARCH('Spam Rules'!$A$22:$A$35,K4)))>0,1,0) -> 0 | S4: =IF(AND(F4="Free",G4=""),1,0) -> 0 | T4: =IF(LEN(TRIM(K4))<15,1,0) -> 0 | U4: =IF(COUNTIF($E$2:$E$801,E4)>1,1,0) -> 0 | V4: =Q4*'Spam Rules'!$H$6+R4*'Spam Rules'!$H$7+S4*'Spam Rules'!$H$8+T4*'Spam Rules'!$H$9+U4*'Spam Rules'!$H$10 -> 0 | W4: =IF(V4>='Spam Rules'!$B$3,"Likely Spam","Genuine") -> Genuine | X4: =IFERROR(INDEX('Scoring Model'!$B$5:$B$11,MATCH(C4,'Scoring Model'!$A$5:$A$11,0)),0) -> 10 | Y4: =IFERROR(INDEX('Scoring Model'!$E$5:$E$7,MATCH(F4,'Scoring Model'!$D$5:$D$7,0)),0) -> 0 | Z4: =IFERROR(INDEX('Scoring Model'!$H$5:$H$13,MATCH(J4,'Scoring Model'!$G$5:$G$13,0)),0) -> 0 | AA4: =IF(L4>='Scoring Model'!$B$14,'Scoring Model'!$B$15,IF(L4>='Scoring Model'!$B$16,'Scoring Model'!$B$17,0)) -> 0 | AB4: =IF(SUMPRODUCT(--ISNUMBER(SEARCH('Scoring Model'!$D$16:$D$25,K4)))>0,'Scoring Model'!$B$18,0) -> 0 | AC4: =IF(SUMPRODUCT(--ISNUMBER(SEARCH('Scoring Model'!$G$16:$G$23,K4)))>0,'Scoring Model'!$B$19,0) -> -30 | AD4: =IF(W4="Likely Spam","",SUM(X4:AC4)) -> -20 | AE4: =IF(W4="Likely Spam","Spam",IF(AD4>='Scoring Model'!$B$21,"Hot",IF(AD4>='Scoring Model'!$B$22,"Warm","Nurture"))) -> Nurture | AF4: =IF(W4="Likely Spam","Flagged by spam rules",TRIM(IF(X4>=20,"Strong source. ","")&IF(Y4>0,"Company email. ","")&IF(Z4>=15,"High-value product. ","")&IF(AA4>='Scoring Model'!$B$15,"High engagement. ","")&IF(AB4>0,"Buying intent in message. ","")&IF(AC4<0,"Negative intent in message. ",""))) -> Negative intent in message. | AG4: =IF(W4="Likely Spam","",1/(1+EXP(-('Conversion Model'!$B$5+IFERROR(INDEX('Conversion Model'!$B$8:$B$14,MATCH(C4,'Conversion Model'!$A$8:$A$14,0)),0)+IFERROR(INDEX('Conversion Model'!$E$8:$E$9,MATCH(F4,'Conversion Model'!$D$8:$D$9,0)),0)+IFERROR(INDEX('Conversion Model'!$H$8:$H$12,MATCH(IF(LEFT(J4,8)="Payments","Payments",IF(LEFT(J4,7)="Lending","Lending",J4)),'Conversion Model'!$G$8:$G$12,0)),0)+MIN(L4,15)*'Conversion Model'!$B$17+IF(SUMPRODUCT(--ISNUMBER(SEARCH('Scoring Model'!$D$16:$D$25,K4)))>0,'Conversion Model'!$B$18,0)+IF(SUMPRODUCT(--ISNUMBER(SEARCH('Scoring Model'!$G$16:$G$23,K4)))>0,'Conversion Model'!$B$19,0))))) -> 0.00206615 | AH4: =IF(OR(O4="Qualified",O4="Won",O4="Lost"),1,IF(O4="Unqualified",0,""))
A5: L-0004 | B5: 45934.185 | C5: Chat Widget | D5: Daniel Costa | E5: daniel257@inboxly.example | F5: Free | G5: Listpeak Directory | I5: Singapore | J5: KYC Verification | K5: Get your app listing on top review sites in 48 hours, guaranteed. Contact our listing agent. | L5: 1 | M5: 10.7 | N5: Unassigned | Q5: =IF(F5="Disposable",1,0) -> 0 | R5: =IF(SUMPRODUCT(--ISNUMBER(SEARCH('Spam Rules'!$A$22:$A$35,K5)))>0,1,0) -> 1 | S5: =IF(AND(F5="Free",G5=""),1,0) -> 0 | T5: =IF(LEN(TRIM(K5))<15,1,0) -> 0 | U5: =IF(COUNTIF($E$2:$E$801,E5)>1,1,0) -> 0 | V5: =Q5*'Spam Rules'!$H$6+R5*'Spam Rules'!$H$7+S5*'Spam Rules'!$H$8+T5*'Spam Rules'!$H$9+U5*'Spam Rules'!$H$10 -> 1 | W5: =IF(V5>='Spam Rules'!$B$3,"Likely Spam","Genuine") -> Likely Spam | X5: =IFERROR(INDEX('Scoring Model'!$B$5:$B$11,MATCH(C5,'Scoring Model'!$A$5:$A$11,0)),0) -> 0 | Y5: =IFERROR(INDEX('Scoring Model'!$E$5:$E$7,MATCH(F5,'Scoring Model'!$D$5:$D$7,0)),0) -> 0 | Z5: =IFERROR(INDEX('Scoring Model'!$H$5:$H$13,MATCH(J5,'Scoring Model'!$G$5:$G$13,0)),0) -> 5 | AA5: =IF(L5>='Scoring Model'!$B$14,'Scoring Model'!$B$15,IF(L5>='Scoring Model'!$B$16,'Scoring Model'!$B$17,0)) -> 0 | AB5: =IF(SUMPRODUCT(--ISNUMBER(SEARCH('Scoring Model'!$D$16:$D$25,K5)))>0,'Scoring Model'!$B$18,0) -> 0 | AC5: =IF(SUMPRODUCT(--ISNUMBER(SEARCH('Scoring Model'!$G$16:$G$23,K5)))>0,'Scoring Model'!$B$19,0) -> 0 | AD5: =IF(W5="Likely Spam","",SUM(X5:AC5)) | AE5: =IF(W5="Likely Spam","Spam",IF(AD5>='Scoring Model'!$B$21,"Hot",IF(AD5>='Scoring Model'!$B$22,"Warm","Nurture"))) -> Spam | AF5: =IF(W5="Likely Spam","Flagged by spam rules",TRIM(IF(X5>=20,"Strong source. ","")&IF(Y5>0,"Company email. ","")&IF(Z5>=15,"High-value product. ","")&IF(AA5>='Scoring Model'!$B$15,"High engagement. ","")&IF(AB5>0,"Buying intent in message. ","")&IF(AC5<0,"Negative intent in message. ",""))) -> Flagged by spam rules | AG5: =IF(W5="Likely Spam","",1/(1+EXP(-('Conversion Model'!$B$5+IFERROR(INDEX('Conversion Model'!$B$8:$B$14,MATCH(C5,'Conversion Model'!$A$8:$A$14,0)),0)+IFERROR(INDEX('Conversion Model'!$E$8:$E$9,MATCH(F5,'Conversion Model'!$D$8:$D$9,0)),0)+IFERROR(INDEX('Conversion Model'!$H$8:$H$12,MATCH(IF(LEFT(J5,8)="Payments","Payments",IF(LEFT(J5,7)="Lending","Lending",J5)),'Conversion Model'!$G$8:$G$12,0)),0)+MIN(L5,15)*'Conversion Model'!$B$17+IF(SUMPRODUCT(--ISNUMBER(SEARCH('Scoring Model'!$D$16:$D$25,K5)))>0,'Conversion Model'!$B$18,0)+IF(SUMPRODUCT(--ISNUMBER(SEARCH('Scoring Model'!$G$16:$G$23,K5)))>0,'Conversion Model'!$B$19,0))))) | AH5: =IF(OR(O5="Qualified",O5="Won",O5="Lost"),1,IF(O5="Unqualified",0,""))
A6: L-0005 | B6: 45934.661 | C6: Chat Widget | D6: Ethan Silva | E6: ethan460@codewhistleoutsourcing.example | F6: Company | G6: Codewhistle Outsourcing | H6: https://codewhistleoutsourcing.example | I6: India | J6: Other | K6: Claim your cashback reward now at the link below. | L6: 2 | M6: 24.1 | N6: Unassigned | O6: Spam | Q6: =IF(F6="Disposable",1,0) -> 0 | R6: =IF(SUMPRODUCT(--ISNUMBER(SEARCH('Spam Rules'!$A$22:$A$35,K6)))>0,1,0) -> 1 | S6: =IF(AND(F6="Free",G6=""),1,0) -> 0 | T6: =IF(LEN(TRIM(K6))<15,1,0) -> 0 | U6: =IF(COUNTIF($E$2:$E$801,E6)>1,1,0) -> 0 | V6: =Q6*'Spam Rules'!$H$6+R6*'Spam Rules'!$H$7+S6*'Spam Rules'!$H$8+T6*'Spam Rules'!$H$9+U6*'Spam Rules'!$H$10 -> 1 | W6: =IF(V6>='Spam Rules'!$B$3,"Likely Spam","Genuine") -> Likely Spam | X6: =IFERROR(INDEX('Scoring Model'!$B$5:$B$11,MATCH(C6,'Scoring Model'!$A$5:$A$11,0)),0) -> 0 | Y6: =IFERROR(INDEX('Scoring Model'!$E$5:$E$7,MATCH(F6,'Scoring Model'!$D$5:$D$7,0)),0) -> 20 | Z6: =IFERROR(INDEX('Scoring Model'!$H$5:$H$13,MATCH(J6,'Scoring Model'!$G$5:$G$13,0)),0) -> 0 | AA6: =IF(L6>='Scoring Model'!$B$14,'Scoring Model'!$B$15,IF(L6>='Scoring Model'!$B$16,'Scoring Model'!$B$17,0)) -> 0 | AB6: =IF(SUMPRODUCT(--ISNUMBER(SEARCH('Scoring Model'!$D$16:$D$25,K6)))>0,'Scoring Model'!$B$18,0) -> 0 | AC6: =IF(SUMPRODUCT(--ISNUMBER(SEARCH('Scoring Model'!$G$16:$G$23,K6)))>0,'Scoring Model'!$B$19,0) -> 0 | AD6: =IF(W6="Likely Spam","",SUM(X6:AC6)) | AE6: =IF(W6="Likely Spam","Spam",IF(AD6>='Scoring Model'!$B$21,"Hot",IF(AD6>='Scoring Model'!$B$22,"Warm","Nurture"))) -> Spam | AF6: =IF(W6="Likely Spam","Flagged by spam rules",TRIM(IF(X6>=20,"Strong source. ","")&IF(Y6>0,"Company email. ","")&IF(Z6>=15,"High-value product. ","")&IF(AA6>='Scoring Model'!$B$15,"High engagement. ","")&IF(AB6>0,"Buying intent in message. ","")&IF(AC6<0,"Negative intent in message. ",""))) -> Flagged by spam rules | AG6: =IF(W6="Likely Spam","",1/(1+EXP(-('Conversion Model'!$B$5+IFERROR(INDEX('Conversion Model'!$B$8:$B$14,MATCH(C6,'Conversion Model'!$A$8:$A$14,0)),0)+IFERROR(INDEX('Conversion Model'!$E$8:$E$9,MATCH(F6,'Conversion Model'!$D$8:$D$9,0)),0)+IFERROR(INDEX('Conversion Model'!$H$8:$H$12,MATCH(IF(LEFT(J6,8)="Payments","Payments",IF(LEFT(J6,7)="Lending","Lending",J6)),'Conversion Model'!$G$8:$G$12,0)),0)+MIN(L6,15)*'Conversion Model'!$B$17+IF(SUMPRODUCT(--ISNUMBER(SEARCH('Scoring Model'!$D$16:$D$25,K6)))>0,'Conversion Model'!$B$18,0)+IF(SUMPRODUCT(--ISNUMBER(SEARCH('Scoring Model'!$G$16:$G$23,K6)))>0,'Conversion Model'!$B$19,0))))) | AH6: =IF(OR(O6="Qualified",O6="Won",O6="Lost"),1,IF(O6="Unqualified",0,""))
A7: L-0006 | B7: 45935.012 | C7: Docs Signup | D7: Chloe Tanaka | E7: noah26@postbox.example | F7: Disposable | I7: Japan | J7: Other | K7: Partnership proposal for fintech influencer marketing campaign, 500k reach. | L7: 2 | M7: 99.9 | N7: Rahul | Q7: =IF(F7="Disposable",1,0) -> 1 | R7: =IF(SUMPRODUCT(--ISNUMBER(SEARCH('Spam Rules'!$A$22:$A$35,K7)))>0,1,0) -> 1 | S7: =IF(AND(F7="Free",G7=""),1,0) -> 0 | T7: =IF(LEN(TRIM(K7))<15,1,0) -> 0 | U7: =IF(COUNTIF($E$2:$E$801,E7)>1,1,0) -> 1 | V7: =Q7*'Spam Rules'!$H$6+R7*'Spam Rules'!$H$7+S7*'Spam Rules'!$H$8+T7*'Spam Rules'!$H$9+U7*'Spam Rules'!$H$10 -> 2 | W7: =IF(V7>='Spam Rules'!$B$3,"Likely Spam","Genuine") -> Likely Spam | X7: =IFERROR(INDEX('Scoring Model'!$B$5:$B$11,MATCH(C7,'Scoring Model'!$A$5:$A$11,0)),0) -> 5 | Y7: =IFERROR(INDEX('Scoring Model'!$E$5:$E$7,MATCH(F7,'Scoring Model'!$D$5:$D$7,0)),0) -> 0 | Z7: =IFERROR(INDEX('Scoring Model'!$H$5:$H$13,MATCH(J7,'Scoring Model'!$G$5:$G$13,0)),0) -> 0 | AA7: =IF(L7>='Scoring Model'!$B$14,'Scoring Model'!$B$15,IF(L7>='Scoring Model'!$B$16,'Scoring Model'!$B$17,0)) -> 0 | AB7: =IF(SUMPRODUCT(--ISNUMBER(SEARCH('Scoring Model'!$D$16:$D$25,K7)))>0,'Scoring Model'!$B$18,0) -> 0 | AC7: =IF(SUMPRODUCT(--ISNUMBER(SEARCH('Scoring Model'!$G$16:$G$23,K7)))>0,'Scoring Model'!$B$19,0) -> 0 | AD7: =IF(W7="Likely Spam","",SUM(X7:AC7)) | AE7: =IF(W7="Likely Spam","Spam",IF(AD7>='Scoring Model'!$B$21,"Hot",IF(AD7>='Scoring Model'!$B$22,"Warm","Nurture"))) -> Spam | AF7: =IF(W7="Likely Spam","Flagged by spam rules",TRIM(IF(X7>=20,"Strong source. ","")&IF(Y7>0,"Company email. ","")&IF(Z7>=15,"High-value product. ","")&IF(AA7>='Scoring Model'!$B$15,"High engagement. ","")&IF(AB7>0,"Buying intent in message. ","")&IF(AC7<0,"Negative intent in message. ",""))) -> Flagged by spam rules | AG7: =IF(W7="Likely Spam","",1/(1+EXP(-('Conversion Model'!$B$5+IFERROR(INDEX('Conversion Model'!$B$8:$B$14,MATCH(C7,'Conversion Model'!$A$8:$A$14,0)),0)+IFERROR(INDEX('Conversion Model'!$E$8:$E$9,MATCH(F7,'Conversion Model'!$D$8:$D$9,0)),0)+IFERROR(INDEX('Conversion Model'!$H$8:$H$12,MATCH(IF(LEFT(J7,8)="Payments","Payments",IF(LEFT(J7,7)="Lending","Lending",J7)),'Conversion Model'!$G$8:$G$12,0)),0)+MIN(L7,15)*'Conversion Model'!$B$17+IF(SUMPRODUCT(--ISNUMBER(SEARCH('Scoring Model'!$D$16:$D$25,K7)))>0,'Conversion Model'!$B$18,0)+IF(SUMPRODUCT(--ISNUMBER(SEARCH('Scoring Model'!$G$16:$G$23,K7)))>0,'Conversion Model'!$B$19,0))))) | AH7: =IF(OR(O7="Qualified",O7="Won",O7="Lost"),1,IF(O7="Unqualified",0,""))
A8: L-0007 | B8: 45935.153 | C8: Docs Signup | D8: Mateo Haddad | E8: mateo.haddad@webmail.example | F8: Free | G8: Zellowmark Labs | I8: Japan | J8: Other | K8: Can I use your API for a personal budget tracker? | L8: 4 | M8: 8.4 | N8: Vikram | Q8: =IF(F8="Disposable",1,0) -> 0 | R8: =IF(SUMPRODUCT(--ISNUMBER(SEARCH('Spam Rules'!$A$22:$A$35,K8)))>0,1,0) -> 0 | S8: =IF(AND(F8="Free",G8=""),1,0) -> 0 | T8: =IF(LEN(TRIM(K8))<15,1,0) -> 0 | U8: =IF(COUNTIF($E$2:$E$801,E8)>1,1,0) -> 0 | V8: =Q8*'Spam Rules'!$H$6+R8*'Spam Rules'!$H$7+S8*'Spam Rules'!$H$8+T8*'Spam Rules'!$H$9+U8*'Spam Rules'!$H$10 -> 0 | W8: =IF(V8>='Spam Rules'!$B$3,"Likely Spam","Genuine") -> Genuine | X8: =IFERROR(INDEX('Scoring Model'!$B$5:$B$11,MATCH(C8,'Scoring Model'!$A$5:$A$11,0)),0) -> 5 | Y8: =IFERROR(INDEX('Scoring Model'!$E$5:$E$7,MATCH(F8,'Scoring Model'!$D$5:$D$7,0)),0) -> 0 | Z8: =IFERROR(INDEX('Scoring Model'!$H$5:$H$13,MATCH(J8,'Scoring Model'!$G$5:$G$13,0)),0) -> 0 | AA8: =IF(L8>='Scoring Model'!$B$14,'Scoring Model'!$B$15,IF(L8>='Scoring Model'!$B$16,'Scoring Model'!$B$17,0)) -> 8 | AB8: =IF(SUMPRODUCT(--ISNUMBER(SEARCH('Scoring Model'!$D$16:$D$25,K8)))>0,'Scoring Model'!$B$18,0) -> 0 | AC8: =IF(SUMPRODUCT(--ISNUMBER(SEARCH('Scoring Model'!$G$16:$G$23,K8)))>0,'Scoring Model'!$B$19,0) -> -30 | AD8: =IF(W8="Likely Spam","",SUM(X8:AC8)) -> -17 | AE8: =IF(W8="Likely Spam","Spam",IF(AD8>='Scoring Model'!$B$21,"Hot",IF(AD8>='Scoring Model'!$B$22,"Warm","Nurture"))) -> Nurture | AF8: =IF(W8="Likely Spam","Flagged by spam rules",TRIM(IF(X8>=20,"Strong source. ","")&IF(Y8>0,"Company email. ","")&IF(Z8>=15,"High-value product. ","")&IF(AA8>='Scoring Model'!$B$15,"High engagement. ","")&IF(AB8>0,"Buying intent in message. ","")&IF(AC8<0,"Negative intent in message. ",""))) -> Negative intent in message. | AG8: =IF(W8="Likely Spam","",1/(1+EXP(-('Conversion Model'!$B$5+IFERROR(INDEX('Conversion Model'!$B$8:$B$14,MATCH(C8,'Conversion Model'!$A$8:$A$14,0)),0)+IFERROR(INDEX('Conversion Model'!$E$8:$E$9,MATCH(F8,'Conversion Model'!$D$8:$D$9,0)),0)+IFERROR(INDEX('Conversion Model'!$H$8:$H$12,MATCH(IF(LEFT(J8,8)="Payments","Payments",IF(LEFT(J8,7)="Lending","Lending",J8)),'Conversion Model'!$G$8:$G$12,0)),0)+MIN(L8,15)*'Conversion Model'!$B$17+IF(SUMPRODUCT(--ISNUMBER(SEARCH('Scoring Model'!$D$16:$D$25,K8)))>0,'Conversion Model'!$B$18,0)+IF(SUMPRODUCT(--ISNUMBER(SEARCH('Scoring Model'!$G$16:$G$23,K8)))>0,'Conversion Model'!$B$19,0))))) -> 0.0074801067 | AH8: =IF(OR(O8="Qualified",O8="Won",O8="Lost"),1,IF(O8="Unqualified",0,""))
A9: L-0008 | B9: 45935.308 | C9: Website Contact Form | D9: Nadia Costa | E9: nadia.costa@larkspindlewallet.example | F9: Company | G9: Larkspindle Wallet | H9: https://larkspindlewallet.example | I9: Turkey | J9: Payments - Payouts | K9: Evaluating payouts providers for our loyalty app. Can we get a demo and a cost comparison? | L9: 9 | M9: 88 | N9: Unassigned | O9: Lost | Q9: =IF(F9="Disposable",1,0) -> 0 | R9: =IF(SUMPRODUCT(--ISNUMBER(SEARCH('Spam Rules'!$A$22:$A$35,K9)))>0,1,0) -> 0 | S9: =IF(AND(F9="Free",G9=""),1,0) -> 0 | T9: =IF(LEN(TRIM(K9))<15,1,0) -> 0 | U9: =IF(COUNTIF($E$2:$E$801,E9)>1,1,0) -> 0 | V9: =Q9*'Spam Rules'!$H$6+R9*'Spam Rules'!$H$7+S9*'Spam Rules'!$H$8+T9*'Spam Rules'!$H$9+U9*'Spam Rules'!$H$10 -> 0 | W9: =IF(V9>='Spam Rules'!$B$3,"Likely Spam","Genuine") -> Genuine | X9: =IFERROR(INDEX('Scoring Model'!$B$5:$B$11,MATCH(C9,'Scoring Model'!$A$5:$A$11,0)),0) -> 10 | Y9: =IFERROR(INDEX('Scoring Model'!$E$5:$E$7,MATCH(F9,'Scoring Model'!$D$5:$D$7,0)),0) -> 20 | Z9: =IFERROR(INDEX('Scoring Model'!$H$5:$H$13,MATCH(J9,'Scoring Model'!$G$5:$G$13,0)),0) -> 15 | AA9: =IF(L9>='Scoring Model'!$B$14,'Scoring Model'!$B$15,IF(L9>='Scoring Model'!$B$16,'Scoring Model'!$B$17,0)) -> 15 | AB9: =IF(SUMPRODUCT(--ISNUMBER(SEARCH('Scoring Model'!$D$16:$D$25,K9)))>0,'Scoring Model'!$B$18,0) -> 15 | AC9: =IF(SUMPRODUCT(--ISNUMBER(SEARCH('Scoring Model'!$G$16:$G$23,K9)))>0,'Scoring Model'!$B$19,0) -> 0 | AD9: =IF(W9="Likely Spam","",SUM(X9:AC9)) -> 75 | AE9: =IF(W9="Likely Spam","Spam",IF(AD9>='Scoring Model'!$B$21,"Hot",IF(AD9>='Scoring Model'!$B$22,"Warm","Nurture"))) -> Hot | AF9: =IF(W9="Likely Spam","Flagged by spam rules",TRIM(IF(X9>=20,"Strong source. ","")&IF(Y9>0,"Company email. ","")&IF(Z9>=15,"High-value product. ","")&IF(AA9>='Scoring Model'!$B$15,"High engagement. ","")&IF(AB9>0,"Buying intent in message. ","")&IF(AC9<0,"Negative intent in message. ",""))) -> Company email. High-value product. High engagement. Buying intent in message. | AG9: =IF(W9="Likely Spam","",1/(1+EXP(-('Conversion Model'!$B$5+IFERROR(INDEX('Conversion Model'!$B$8:$B$14,MATCH(C9,'Conversion Model'!$A$8:$A$14,0)),0)+IFERROR(INDEX('Conversion Model'!$E$8:$E$9,MATCH(F9,'Conversion Model'!$D$8:$D$9,0)),0)+IFERROR(INDEX('Conversion Model'!$H$8:$H$12,MATCH(IF(LEFT(J9,8)="Payments","Payments",IF(LEFT(J9,7)="Lending","Lending",J9)),'Conversion Model'!$G$8:$G$12,0)),0)+MIN(L9,15)*'Conversion Model'!$B$17+IF(SUMPRODUCT(--ISNUMBER(SEARCH('Scoring Model'!$D$16:$D$25,K9)))>0,'Conversion Model'!$B$18,0)+IF(SUMPRODUCT(--ISNUMBER(SEARCH('Scoring Model'!$G$16:$G$23,K9)))>0,'Conversion Model'!$B$19,0))))) -> 0.98188973 | AH9: =IF(OR(O9="Qualified",O9="Won",O9="Lost"),1,IF(O9="Unqualified",0,"")) -> 1
A10: L-0009 | B10: 45935.376 | C10: Event | D10: Mateo Okafor | E10: mateo.okafor@freemail.example | F10: Free | G10: Vexmoor Labs | I10: Brazil | J10: Lending - Credit Scoring | K10: Looking for pricing on KYC verification across 5 countries. Our current vendor keeps missing checks. | L10: 3 | M10: 3.6 | N10: Rahul | Q10: =IF(F10="Disposable",1,0) -> 0 | R10: =IF(SUMPRODUCT(--ISNUMBER(SEARCH('Spam Rules'!$A$22:$A$35,K10)))>0,1,0) -> 0 | S10: =IF(AND(F10="Free",G10=""),1,0) -> 0 | T10: =IF(LEN(TRIM(K10))<15,1,0) -> 0 | U10: =IF(COUNTIF($E$2:$E$801,E10)>1,1,0) -> 0 | V10: =Q10*'Spam Rules'!$H$6+R10*'Spam Rules'!$H$7+S10*'Spam Rules'!$H$8+T10*'Spam Rules'!$H$9+U10*'Spam Rules'!$H$10 -> 0 | W10: =IF(V10>='Spam Rules'!$B$3,"Likely Spam","Genuine") -> Genuine | X10: =IFERROR(INDEX('Scoring Model'!$B$5:$B$11,MATCH(C10,'Scoring Model'!$A$5:$A$11,0)),0) -> 15 | Y10: =IFERROR(INDEX('Scoring Model'!$E$5:$E$7,MATCH(F10,'Scoring Model'!$D$5:$D$7,0)),0) -> 0 | Z10: =IFERROR(INDEX('Scoring Model'!$H$5:$H$13,MATCH(J10,'Scoring Model'!$G$5:$G$13,0)),0) -> 15 | AA10: =IF(L10>='Scoring Model'!$B$14,'Scoring Model'!$B$15,IF(L10>='Scoring Model'!$B$16,'Scoring Model'!$B$17,0)) -> 0 | AB10: =IF(SUMPRODUCT(--ISNUMBER(SEARCH('Scoring Model'!$D$16:$D$25,K10)))>0,'Scoring Model'!$B$18,0) -> 15 | AC10: =IF(SUMPRODUCT(--ISNUMBER(SEARCH('Scoring Model'!$G$16:$G$23,K10)))>0,'Scoring Model'!$B$19,0) -> 0 | AD10: =IF(W10="Likely Spam","",SUM(X10:AC10)) -> 45 | AE10: =IF(W10="Likely Spam","Spam",IF(AD10>='Scoring Model'!$B$21,"Hot",IF(AD10>='Scoring Model'!$B$22,"Warm","Nurture"))) -> Warm | AF10: =IF(W10="Likely Spam","Flagged by spam rules",TRIM(IF(X10>=20,"Strong source. ","")&IF(Y10>0,"Company email. ","")&IF(Z10>=15,"High-value product. ","")&IF(AA10>='Scoring Model'!$B$15,"High engagement. ","")&IF(AB10>0,"Buying intent in message. ","")&IF(AC10<0,"Negative intent in message. ",""))) -> High-value product. Buying intent in message. | AG10: =IF(W10="Likely Spam","",1/(1+EXP(-('Conversion Model'!$B$5+IFERROR(INDEX('Conversion Model'!$B$8:$B$14,MATCH(C10,'Conversion Model'!$A$8:$A$14,0)),0)+IFERROR(INDEX('Conversion Model'!$E$8:$E$9,MATCH(F10,'Conversion Model'!$D$8:$D$9,0)),0)+IFERROR(INDEX('Conversion Model'!$H$8:$H$12,MATCH(IF(LEFT(J10,8)="Payments","Payments",IF(LEFT(J10,7)="Lending","Lending",J10)),'Conversion Model'!$G$8:$G$12,0)),0)+MIN(L10,15)*'Conversion Model'!$B$17+IF(SUMPRODUCT(--ISNUMBER(SEARCH('Scoring Model'!$D$16:$D$25,K10)))>0,'Conversion Model'!$B$18,0)+IF(SUMPRODUCT(--ISNUMBER(SEARCH('Scoring Model'!$G$16:$G$23,K10)))>0,'Conversion Model'!$B$19,0))))) -> 0.32431757 | AH10: =IF(OR(O10="Qualified",O10="Won",O10="Lost"),1,IF(O10="Unqualified",0,""))
A11: L-0010 | B11: 45935.827 | C11: Website Contact Form | D11: Ji-woo Brown | E11: noah877@letterdrop.example | F11: Disposable | I11: Brazil | J11: Payments - Card Issuing | K11: Boost your Twitter followers and Telegram members, organic fintech marketing. | L11: 1 | N11: Unassigned | O11: Spam | Q11: =IF(F11="Disposable",1,0) -> 1 | R11: =IF(SUMPRODUCT(--ISNUMBER(SEARCH('Spam Rules'!$A$22:$A$35,K11)))>0,1,0) -> 1 | S11: =IF(AND(F11="Free",G11=""),1,0) -> 0 | T11: =IF(LEN(TRIM(K11))<15,1,0) -> 0 | U11: =IF(COUNTIF($E$2:$E$801,E11)>1,1,0) -> 1 | V11: =Q11*'Spam Rules'!$H$6+R11*'Spam Rules'!$H$7+S11*'Spam Rules'!$H$8+T11*'Spam Rules'!$H$9+U11*'Spam Rules'!$H$10 -> 2 | W11: =IF(V11>='Spam Rules'!$B$3,"Likely Spam","Genuine") -> Likely Spam | X11: =IFERROR(INDEX('Scoring Model'!$B$5:$B$11,MATCH(C11,'Scoring Model'!$A$5:$A$11,0)),0) -> 10 | Y11: =IFERROR(INDEX('Scoring Model'!$E$5:$E$7,MATCH(F11,'Scoring Model'!$D$5:$D$7,0)),0) -> 0 | Z11: =IFERROR(INDEX('Scoring Model'!$H$5:$H$13,MATCH(J11,'Scoring Model'!$G$5:$G$13,0)),0) -> 15 | AA11: =IF(L11>='Scoring Model'!$B$14,'Scoring Model'!$B$15,IF(L11>='Scoring Model'!$B$16,'Scoring Model'!$B$17,0)) -> 0 | AB11: =IF(SUMPRODUCT(--ISNUMBER(SEARCH('Scoring Model'!$D$16:$D$25,K11)))>0,'Scoring Model'!$B$18,0) -> 0 | AC11: =IF(SUMPRODUCT(--ISNUMBER(SEARCH('Scoring Model'!$G$16:$G$23,K11)))>0,'Scoring Model'!$B$19,0) -> 0 | AD11: =IF(W11="Likely Spam","",SUM(X11:AC11)) | AE11: =IF(W11="Likely Spam","Spam",IF(AD11>='Scoring Model'!$B$21,"Hot",IF(AD11>='Scoring Model'!$B$22,"Warm","Nurture"))) -> Spam | AF11: =IF(W11="Likely Spam","Flagged by spam rules",TRIM(IF(X11>=20,"Strong source. ","")&IF(Y11>0,"Company email. ","")&IF(Z11>=15,"High-value product. ","")&IF(AA11>='Scoring Model'!$B$15,"High engagement. ","")&IF(AB11>0,"Buying intent in message. ","")&IF(AC11<0,"Negative intent in message. ",""))) -> Flagged by spam rules | AG11: =IF(W11="Likely Spam","",1/(1+EXP(-('Conversion Model'!$B$5+IFERROR(INDEX('Conversion Model'!$B$8:$B$14,MATCH(C11,'Conversion Model'!$A$8:$A$14,0)),0)+IFERROR(INDEX('Conversion Model'!$E$8:$E$9,MATCH(F11,'Conversion Model'!$D$8:$D$9,0)),0)+IFERROR(INDEX('Conversion Model'!$H$8:$H$12,MATCH(IF(LEFT(J11,8)="Payments","Payments",IF(LEFT(J11,7)="Lending","Lending",J11)),'Conversion Model'!$G$8:$G$12,0)),0)+MIN(L11,15)*'Conversion Model'!$B$17+IF(SUMPRODUCT(--ISNUMBER(SEARCH('Scoring Model'!$D$16:$D$25,K11)))>0,'Conversion Model'!$B$18,0)+IF(SUMPRODUCT(--ISNUMBER(SEARCH('Scoring Model'!$G$16:$G$23,K11)))>0,'Conversion Model'!$B$19,0))))) | AH11: =IF(OR(O11="Qualified",O11="Won",O11="Lost"),1,IF(O11="Unqualified",0,""))
A12: L-0011 | B12: 45935.905 | C12: Chat Widget | D12: Zara Kim | E12: zara780@letterdrop.example | F12: Free | I12: UK | J12: KYC Verification | K12: hi | L12: 2 | N12: Unassigned | O12: Spam | Q12: =IF(F12="Disposable",1,0) -> 0 | R12: =IF(SUMPRODUCT(--ISNUMBER(SEARCH('Spam Rules'!$A$22:$A$35,K12)))>0,1,0) -> 0 | S12: =IF(AND(F12="Free",G12=""),1,0) -> 1 | T12: =IF(LEN(TRIM(K12))<15,1,0) -> 1 | U12: =IF(COUNTIF($E$2:$E$801,E12)>1,1,0) -> 0 | V12: =Q12*'Spam Rules'!$H$6+R12*'Spam Rules'!$H$7+S12*'Spam Rules'!$H$8+T12*'Spam Rules'!$H$9+U12*'Spam Rules'!$H$10 -> 1 | W12: =IF(V12>='Spam Rules'!$B$3,"Likely Spam","Genuine") -> Likely Spam | X12: =IFERROR(INDEX('Scoring Model'!$B$5:$B$11,MATCH(C12,'Scoring Model'!$A$5:$A$11,0)),0) -> 0 | Y12: =IFERROR(INDEX('Scoring Model'!$E$5:$E$7,MATCH(F12,'Scoring Model'!$D$5:$D$7,0)),0) -> 0 | Z12: =IFERROR(INDEX('Scoring Model'!$H$5:$H$13,MATCH(J12,'Scoring Model'!$G$5:$G$13,0)),0) -> 5 | AA12: =IF(L12>='Scoring Model'!$B$14,'Scoring Model'!$B$15,IF(L12>='Scoring Model'!$B$16,'Scoring Model'!$B$17,0)) -> 0 | AB12: =IF(SUMPRODUCT(--ISNUMBER(SEARCH('Scoring Model'!$D$16:$D$25,K12)))>0,'Scoring Model'!$B$18,0) -> 0 | AC12: =IF(SUMPRODUCT(--ISNUMBER(SEARCH('Scoring Model'!$G$16:$G$23,K12)))>0,'Scoring Model'!$B$19,0) -> 0 | AD12: =IF(W12="Likely Spam","",SUM(X12:AC12)) | AE12: =IF(W12="Likely Spam","Spam",IF(AD12>='Scoring Model'!$B$21,"Hot",IF(AD12>='Scoring Model'!$B$22,"Warm","Nurture"))) -> Spam | AF12: =IF(W12="Likely Spam","Flagged by spam rules",TRIM(IF(X12>=20,"Strong source. ","")&IF(Y12>0,"Company email. ","")&IF(Z12>=15,"High-value product. ","")&IF(AA12>='Scoring Model'!$B$15,"High engagement. ","")&IF(AB12>0,"Buying intent in message. ","")&IF(AC12<0,"Negative intent in message. ",""))) -> Flagged by spam rules | AG12: =IF(W12="Likely Spam","",1/(1+EXP(-('Conversion Model'!$B$5+IFERROR(INDEX('Conversion Model'!$B$8:$B$14,MATCH(C12,'Conversion Model'!$A$8:$A$14,0)),0)+IFERROR(INDEX('Conversion Model'!$E$8:$E$9,MATCH(F12,'Conversion Model'!$D$8:$D$9,0)),0)+IFERROR(INDEX('Conversion Model'!$H$8:$H$12,MATCH(IF(LEFT(J12,8)="Payments","Payments",IF(LEFT(J12,7)="Lending","Lending",J12)),'Conversion Model'!$G$8:$G$12,0)),0)+MIN(L12,15)*'Conversion Model'!$B$17+IF(SUMPRODUCT(--ISNUMBER(SEARCH('Scoring Model'!$D$16:$D$25,K12)))>0,'Conversion Model'!$B$18,0)+IF(SUMPRODUCT(--ISNUMBER(SEARCH('Scoring Model'!$G$16:$G$23,K12)))>0,'Conversion Model'!$B$19,0))))) | AH12: =IF(OR(O12="Qualified",O12="Won",O12="Lost"),1,IF(O12="Unqualified",0,""))
A13: L-0012 | B13: 45936.767 | C13: Partner Referral | D13: Mateo Garcia | E13: mateo.garcia@juniperholtcommerce.example | F13: Company | G13: Juniperholt Commerce | H13: https://juniperholtcommerce.example | I13: Japan | J13: KYC Verification | K13: Looking for pricing on KYC verification across 5 countries. Our current vendor keeps missing checks. | L13: 3 | M13: 66.2 | N13: Rahul | O13: Open | Q13: =IF(F13="Disposable",1,0) -> 0 | R13: =IF(SUMPRODUCT(--ISNUMBER(SEARCH('Spam Rules'!$A$22:$A$35,K13)))>0,1,0) -> 0 | S13: =IF(AND(F13="Free",G13=""),1,0) -> 0 | T13: =IF(LEN(TRIM(K13))<15,1,0) -> 0 | U13: =IF(COUNTIF($E$2:$E$801,E13)>1,1,0) -> 0 | V13: =Q13*'Spam Rules'!$H$6+R13*'Spam Rules'!$H$7+S13*'Spam Rules'!$H$8+T13*'Spam Rules'!$H$9+U13*'Spam Rules'!$H$10 -> 0 | W13: =IF(V13>='Spam Rules'!$B$3,"Likely Spam","Genuine") -> Genuine | X13: =IFERROR(INDEX('Scoring Model'!$B$5:$B$11,MATCH(C13,'Scoring Model'!$A$5:$A$11,0)),0) -> 30 | Y13: =IFERROR(INDEX('Scoring Model'!$E$5:$E$7,MATCH(F13,'Scoring Model'!$D$5:$D$7,0)),0) -> 20 | Z13: =IFERROR(INDEX('Scoring Model'!$H$5:$H$13,MATCH(J13,'Scoring Model'!$G$5:$G$13,0)),0) -> 5 | AA13: =IF(L13>='Scoring Model'!$B$14,'Scoring Model'!$B$15,IF(L13>='Scoring Model'!$B$16,'Scoring Model'!$B$17,0)) -> 0 | AB13: =IF(SUMPRODUCT(--ISNUMBER(SEARCH('Scoring Model'!$D$16:$D$25,K13)))>0,'Scoring Model'!$B$18,0) -> 15 | AC13: =IF(SUMPRODUCT(--ISNUMBER(SEARCH('Scoring Model'!$G$16:$G$23,K13)))>0,'Scoring Model'!$B$19,0) -> 0 | AD13: =IF(W13="Likely Spam","",SUM(X13:AC13)) -> 70 | AE13: =IF(W13="Likely Spam","Spam",IF(AD13>='Scoring Model'!$B$21,"Hot",IF(AD13>='Scoring Model'!$B$22,"Warm","Nurture"))) -> Hot | AF13: =IF(W13="Likely Spam","Flagged by spam rules",TRIM(IF(X13>=20,"Strong source. ","")&IF(Y13>0,"Company email. ","")&IF(Z13>=15,"High-value product. ","")&IF(AA13>='Scoring Model'!$B$15,"High engagement. ","")&IF(AB13>0,"Buying intent in message. ","")&IF(AC13<0,"Negative intent in message. ",""))) -> Strong source. Company email. Buying intent in message. | AG13: =IF(W13="Likely Spam","",1/(1+EXP(-('Conversion Model'!$B$5+IFERROR(INDEX('Conversion Model'!$B$8:$B$14,MATCH(C13,'Conversion Model'!$A$8:$A$14,0)),0)+IFERROR(INDEX('Conversion Model'!$E$8:$E$9,MATCH(F13,'Conversion Model'!$D$8:$D$9,0)),0)+IFERROR(INDEX('Conversion Model'!$H$8:$H$12,MATCH(IF(LEFT(J13,8)="Payments","Payments",IF(LEFT(J13,7)="Lending","Lending",J13)),'Conversion Model'!$G$8:$G$12,0)),0)+MIN(L13,15)*'Conversion Model'!$B$17+IF(SUMPRODUCT(--ISNUMBER(SEARCH('Scoring Model'!$D$16:$D$25,K13)))>0,'Conversion Model'!$B$18,0)+IF(SUMPRODUCT(--ISNUMBER(SEARCH('Scoring Model'!$G$16:$G$23,K13)))>0,'Conversion Model'!$B$19,0))))) -> 0.49775002 | AH13: =IF(OR(O13="Qualified",O13="Won",O13="Lost"),1,IF(O13="Unqualified",0,""))
A14: L-0013 | B14: 45937.351 | C14: LinkedIn ABM | D14: Ananya Lee | E14: ananya.lee@webmail.example | F14: Free | G14: Brindlewick Pay | I14: Germany | J14: Payments - Virtual Accounts | K14: We raised a seed round and plan to launch a digital savings platform for SMEs. Want to discuss infrastructure. | L14: 2 | M14: 3 | N14: Vikram | O14: Open | Q14: =IF(F14="Disposable",1,0) -> 0 | R14: =IF(SUMPRODUCT(--ISNUMBER(SEARCH('Spam Rules'!$A$22:$A$35,K14)))>0,1,0) -> 0 | S14: =IF(AND(F14="Free",G14=""),1,0) -> 0 | T14: =IF(LEN(TRIM(K14))<15,1,0) -> 0 | U14: =IF(COUNTIF($E$2:$E$801,E14)>1,1,0) -> 0 | V14: =Q14*'Spam Rules'!$H$6+R14*'Spam Rules'!$H$7+S14*'Spam Rules'!$H$8+T14*'Spam Rules'!$H$9+U14*'Spam Rules'!$H$10 -> 0 | W14: =IF(V14>='Spam Rules'!$B$3,"Likely Spam","Genuine") -> Genuine | X14: =IFERROR(INDEX('Scoring Model'!$B$5:$B$11,MATCH(C14,'Scoring Model'!$A$5:$A$11,0)),0) -> 20 | Y14: =IFERROR(INDEX('Scoring Model'!$E$5:$E$7,MATCH(F14,'Scoring Model'!$D$5:$D$7,0)),0) -> 0 | Z14: =IFERROR(INDEX('Scoring Model'!$H$5:$H$13,MATCH(J14,'Scoring Model'!$G$5:$G$13,0)),0) -> 15 | AA14: =IF(L14>='Scoring Model'!$B$14,'Scoring Model'!$B$15,IF(L14>='Scoring Model'!$B$16,'Scoring Model'!$B$17,0)) -> 0 | AB14: =IF(SUMPRODUCT(--ISNUMBER(SEARCH('Scoring Model'!$D$16:$D$25,K14)))>0,'Scoring Model'!$B$18,0) -> 15 | AC14: =IF(SUMPRODUCT(--ISNUMBER(SEARCH('Scoring Model'!$G$16:$G$23,K14)))>0,'Scoring Model'!$B$19,0) -> 0 | AD14: =IF(W14="Likely Spam","",SUM(X14:AC14)) -> 50 | AE14: =IF(W14="Likely Spam","Spam",IF(AD14>='Scoring Model'!$B$21,"Hot",IF(AD14>='Scoring Model'!$B$22,"Warm","Nurture"))) -> Warm | AF14: =IF(W14="Likely Spam","Flagged by spam rules",TRIM(IF(X14>=20,"Strong source. ","")&IF(Y14>0,"Company email. ","")&IF(Z14>=15,"High-value product. ","")&IF(AA14>='Scoring Model'!$B$15,"High engagement. ","")&IF(AB14>0,"Buying intent in message. ","")&IF(AC14<0,"Negative intent in message. ",""))) -> Strong source. High-value product. Buying intent in message. | AG14: =IF(W14="Likely Spam","",1/(1+EXP(-('Conversion Model'!$B$5+IFERROR(INDEX('Conversion Model'!$B$8:$B$14,MATCH(C14,'Conversion Model'!$A$8:$A$14,0)),0)+IFERROR(INDEX('Conversion Model'!$E$8:$E$9,MATCH(F14,'Conversion Model'!$D$8:$D$9,0)),0)+IFERROR(INDEX('Conversion Model'!$H$8:$H$12,MATCH(IF(LEFT(J14,8)="Payments","Payments",IF(LEFT(J14,7)="Lending","Lending",J14)),'Conversion Model'!$G$8:$G$12,0)),0)+MIN(L14,15)*'Conversion Model'!$B$17+IF(SUMPRODUCT(--ISNUMBER(SEARCH('Scoring Model'!$D$16:$D$25,K14)))>0,'Conversion Model'!$B$18,0)+IF(SUMPRODUCT(--ISNUMBER(SEARCH('Scoring Model'!$G$16:$G$23,K14)))>0,'Conversion Model'!$B$19,0))))) -> 0.16437906 | AH14: =IF(OR(O14="Qualified",O14="Won",O14="Lost"),1,IF(O14="Unqualified",0,""))
A15: L-0014 | B15: 45937.691 | C15: Event | D15: Zara Garcia | E15: zara.garcia@dunmarrowcapital.example | F15: Company | G15: Dunmarrow Capital | H15: https://dunmarrowcapital.example | I15: Singapore | J15: Banking Data API | K15: We are launching a loyalty product and need a managed card issuing setup with go-live in Q2. | L15: 11 | M15: 18.9 | N15: Unassigned | O15: Won | P15: 48000 | Q15: =IF(F15="Disposable",1,0) -> 0 | R15: =IF(SUMPRODUCT(--ISNUMBER(SEARCH('Spam Rules'!$A$22:$A$35,K15)))>0,1,0) -> 0 | S15: =IF(AND(F15="Free",G15=""),1,0) -> 0 | T15: =IF(LEN(TRIM(K15))<15,1,0) -> 0 | U15: =IF(COUNTIF($E$2:$E$801,E15)>1,1,0) -> 0 | V15: =Q15*'Spam Rules'!$H$6+R15*'Spam Rules'!$H$7+S15*'Spam Rules'!$H$8+T15*'Spam Rules'!$H$9+U15*'Spam Rules'!$H$10 -> 0 | W15: =IF(V15>='Spam Rules'!$B$3,"Likely Spam","Genuine") -> Genuine | X15: =IFERROR(INDEX('Scoring Model'!$B$5:$B$11,MATCH(C15,'Scoring Model'!$A$5:$A$11,0)),0) -> 15 | Y15: =IFERROR(INDEX('Scoring Model'!$E$5:$E$7,MATCH(F15,'Scoring Model'!$D$5:$D$7,0)),0) -> 20 | Z15: =IFERROR(INDEX('Scoring Model'!$H$5:$H$13,MATCH(J15,'Scoring Model'!$G$5:$G$13,0)),0) -> 5 | AA15: =IF(L15>='Scoring Model'!$B$14,'Scoring Model'!$B$15,IF(L15>='Scoring Model'!$B$16,'Scoring Model'!$B$17,0)) -> 15 | AB15: =IF(SUMPRODUCT(--ISNUMBER(SEARCH('Scoring Model'!$D$16:$D$25,K15)))>0,'Scoring Model'!$B$18,0) -> 15 | AC15: =IF(SUMPRODUCT(--ISNUMBER(SEARCH('Scoring Model'!$G$16:$G$23,K15)))>0,'Scoring Model'!$B$19,0) -> 0 | AD15: =IF(W15="Likely Spam","",SUM(X15:AC15)) -> 70 | AE15: =IF(W15="Likely Spam","Spam",IF(AD15>='Scoring Model'!$B$21,"Hot",IF(AD15>='Scoring Model'!$B$22,"Warm","Nurture"))) -> Hot | AF15: =IF(W15="Likely Spam","Flagged by spam rules",TRIM(IF(X15>=20,"Strong source. ","")&IF(Y15>0,"Company email. ","")&IF(Z15>=15,"High-value product. ","")&IF(AA15>='Scoring Model'!$B$15,"High engagement. ","")&IF(AB15>0,"Buying intent in message. ","")&IF(AC15<0,"Negative intent in message. ",""))) -> Company email. High engagement. Buying intent in message. | AG15: =IF(W15="Likely Spam","",1/(1+EXP(-('Conversion Model'!$B$5+IFERROR(INDEX('Conversion Model'!$B$8:$B$14,MATCH(C15,'Conversion Model'!$A$8:$A$14,0)),0)+IFERROR(INDEX('Conversion Model'!$E$8:$E$9,MATCH(F15,'Conversion Model'!$D$8:$D$9,0)),0)+IFERROR(INDEX('Conversion Model'!$H$8:$H$12,MATCH(IF(LEFT(J15,8)="Payments","Payments",IF(LEFT(J15,7)="Lending","Lending",J15)),'Conversion Model'!$G$8:$G$12,0)),0)+MIN(L15,15)*'Conversion Model'!$B$17+IF(SUMPRODUCT(--ISNUMBER(SEARCH('Scoring Model'!$D$16:$D$25,K15)))>0,'Conversion Model'!$B$18,0)+IF(SUMPRODUCT(--ISNUMBER(SEARCH('Scoring Model'!$G$16:$G$23,K15)))>0,'Conversion Model'!$B$19,0))))) -> 0.99695438 | AH15: =IF(OR(O15="Qualified",O15="Won",O15="Lost"),1,IF(O15="Unqualified",0,"")) -> 1
A16: L-0015 | B16: 45939.477 | C16: LinkedIn ABM | D16: Ravi Lee | E16: ravi.lee@quarrytidefinance.example | F16: Company | G16: Quarrytide Finance | H16: https://quarrytidefinance.example | I16: Japan | J16: KYC Verification | K16: We are launching a marketplace product and need a managed card issuing setup with go-live in Q2. | L16: 10 | M16: 155.4 | N16: Rahul | O16: Lost | Q16: =IF(F16="Disposable",1,0) -> 0 | R16: =IF(SUMPRODUCT(--ISNUMBER(SEARCH('Spam Rules'!$A$22:$A$35,K16)))>0,1,0) -> 0 | S16: =IF(AND(F16="Free",G16=""),1,0) -> 0 | T16: =IF(LEN(TRIM(K16))<15,1,0) -> 0 | U16: =IF(COUNTIF($E$2:$E$801,E16)>1,1,0) -> 0 | V16: =Q16*'Spam Rules'!$H$6+R16*'Spam Rules'!$H$7+S16*'Spam Rules'!$H$8+T16*'Spam Rules'!$H$9+U16*'Spam Rules'!$H$10 -> 0 | W16: =IF(V16>='Spam Rules'!$B$3,"Likely Spam","Genuine") -> Genuine | X16: =IFERROR(INDEX('Scoring Model'!$B$5:$B$11,MATCH(C16,'Scoring Model'!$A$5:$A$11,0)),0) -> 20 | Y16: =IFERROR(INDEX('Scoring Model'!$E$5:$E$7,MATCH(F16,'Scoring Model'!$D$5:$D$7,0)),0) -> 20 | Z16: =IFERROR(INDEX('Scoring Model'!$H$5:$H$13,MATCH(J16,'Scoring Model'!$G$5:$G$13,0)),0) -> 5 | AA16: =IF(L16>='Scoring Model'!$B$14,'Scoring Model'!$B$15,IF(L16>='Scoring Model'!$B$16,'Scoring Model'!$B$17,0)) -> 15 | AB16: =IF(SUMPRODUCT(--ISNUMBER(SEARCH('Scoring Model'!$D$16:$D$25,K16)))>0,'Scoring Model'!$B$18,0) -> 15 | AC16: =IF(SUMPRODUCT(--ISNUMBER(SEARCH('Scoring Model'!$G$16:$G$23,K16)))>0,'Scoring Model'!$B$19,0) -> 0 | AD16: =IF(W16="Likely Spam","",SUM(X16:AC16)) -> 75 | AE16: =IF(W16="Likely Spam","Spam",IF(AD16>='Scoring Model'!$B$21,"Hot",IF(AD16>='Scoring Model'!$B$22,"Warm","Nurture"))) -> Hot | AF16: =IF(W16="Likely Spam","Flagged by spam rules",TRIM(IF(X16>=20,"Strong source. ","")&IF(Y16>0,"Company email. ","")&IF(Z16>=15,"High-value product. ","")&IF(AA16>='Scoring Model'!$B$15,"High engagement. ","")&IF(AB16>0,"Buying intent in message. ","")&IF(AC16<0,"Negative intent in message. ",""))) -> Strong source. Company email. High engagement. Buying intent in message. | AG16: =IF(W16="Likely Spam","",1/(1+EXP(-('Conversion Model'!$B$5+IFERROR(INDEX('Conversion Model'!$B$8:$B$14,MATCH(C16,'Conversion Model'!$A$8:$A$14,0)),0)+IFERROR(INDEX('Conversion Model'!$E$8:$E$9,MATCH(F16,'Conversion Model'!$D$8:$D$9,0)),0)+IFERROR(INDEX('Conversion Model'!$H$8:$H$12,MATCH(IF(LEFT(J16,8)="Payments","Payments",IF(LEFT(J16,7)="Lending","Lending",J16)),'Conversion Model'!$G$8:$G$12,0)),0)+MIN(L16,15)*'Conversion Model'!$B$17+IF(SUMPRODUCT(--ISNUMBER(SEARCH('Scoring Model'!$D$16:$D$25,K16)))>0,'Conversion Model'!$B$18,0)+IF(SUMPRODUCT(--ISNUMBER(SEARCH('Scoring Model'!$G$16:$G$23,K16)))>0,'Conversion Model'!$B$19,0))))) -> 0.99495851 | AH16: =IF(OR(O16="Qualified",O16="Won",O16="Lost"),1,IF(O16="Unqualified",0,"")) -> 1
A17: L-0016 | B17: 45939.549 | C17: LinkedIn ABM | D17: Lucas Costa | E17: lucas.costa@pellowinstudio.example | F17: Company | G17: Pellowin Studio | H17: https://pellowinstudio.example | I17: Brazil | J17: Payments - Virtual Accounts | K17: We raised a seed round and plan to launch a digital savings platform for SMEs. Want to discuss infrastructure. | L17: 12 | M17: 8.9 | N17: Rahul | O17: Lost | Q17: =IF(F17="Disposable",1,0) -> 0 | R17: =IF(SUMPRODUCT(--ISNUMBER(SEARCH('Spam Rules'!$A$22:$A$35,K17)))>0,1,0) -> 0 | S17: =IF(AND(F17="Free",G17=""),1,0) -> 0 | T17: =IF(LEN(TRIM(K17))<15,1,0) -> 0 | U17: =IF(COUNTIF($E$2:$E$801,E17)>1,1,0) -> 0 | V17: =Q17*'Spam Rules'!$H$6+R17*'Spam Rules'!$H$7+S17*'Spam Rules'!$H$8+T17*'Spam Rules'!$H$9+U17*'Spam Rules'!$H$10 -> 0 | W17: =IF(V17>='Spam Rules'!$B$3,"Likely Spam","Genuine") -> Genuine | X17: =IFERROR(INDEX('Scoring Model'!$B$5:$B$11,MATCH(C17,'Scoring Model'!$A$5:$A$11,0)),0) -> 20 | Y17: =IFERROR(INDEX('Scoring Model'!$E$5:$E$7,MATCH(F17,'Scoring Model'!$D$5:$D$7,0)),0) -> 20 | Z17: =IFERROR(INDEX('Scoring Model'!$H$5:$H$13,MATCH(J17,'Scoring Model'!$G$5:$G$13,0)),0) -> 15 | AA17: =IF(L17>='Scoring Model'!$B$14,'Scoring Model'!$B$15,IF(L17>='Scoring Model'!$B$16,'Scoring Model'!$B$17,0)) -> 15 | AB17: =IF(SUMPRODUCT(--ISNUMBER(SEARCH('Scoring Model'!$D$16:$D$25,K17)))>0,'Scoring Model'!$B$18,0) -> 15 | AC17: =IF(SUMPRODUCT(--ISNUMBER(SEARCH('Scoring Model'!$G$16:$G$23,K17)))>0,'Scoring Model'!$B$19,0) -> 0 | AD17: =IF(W17="Likely Spam","",SUM(X17:AC17)) -> 85 | AE17: =IF(W17="Likely Spam","Spam",IF(AD17>='Scoring Model'!$B$21,"Hot",IF(AD17>='Scoring Model'!$B$22,"Warm","Nurture"))) -> Hot | AF17: =IF(W17="Likely Spam","Flagged by spam rules",TRIM(IF(X17>=20,"Strong source. ","")&IF(Y17>0,"Company email. ","")&IF(Z17>=15,"High-value product. ","")&IF(AA17>='Scoring Model'!$B$15,"High engagement. ","")&IF(AB17>0,"Buying intent in message. ","")&IF(AC17<0,"Negative intent in message. ",""))) -> Strong source. Company email. High-value product. High engagement. Buying intent in message. | AG17: =IF(W17="Likely Spam","",1/(1+EXP(-('Conversion Model'!$B$5+IFERROR(INDEX('Conversion Model'!$B$8:$B$14,MATCH(C17,'Conversion Model'!$A$8:$A$14,0)),0)+IFERROR(INDEX('Conversion Model'!$E$8:$E$9,MATCH(F17,'Conversion Model'!$D$8:$D$9,0)),0)+IFERROR(INDEX('Conversion Model'!$H$8:$H$12,MATCH(IF(LEFT(J17,8)="Payments","Payments",IF(LEFT(J17,7)="Lending","Lending",J17)),'Conversion Model'!$G$8:$G$12,0)),0)+MIN(L17,15)*'Conversion Model'!$B$17+IF(SUMPRODUCT(--ISNUMBER(SEARCH('Scoring Model'!$D$16:$D$25,K17)))>0,'Conversion Model'!$B$18,0)+IF(SUMPRODUCT(--ISNUMBER(SEARCH('Scoring Model'!$G$16:$G$23,K17)))>0,'Conversion Model'!$B$19,0))))) -> 0.99930784 | AH17: =IF(OR(O17="Qualified",O17="Won",O17="Lost"),1,IF(O17="Unqualified",0,"")) -> 1
A18: L-0017 | B18: 45939.909 | C18: Pricing Page Form | D18: Chloe Mehta | E18: chloe.mehta@rushbarrowpay.example | F18: Company | G18: Rushbarrow Pay | H18: https://rushbarrowpay.example | I18: UAE | J18: Payments - Cross-Border | K18: We are launching a loyalty product and need a managed cross-border setup with go-live in Q2. | L18: 12 | M18: 13.7 | N18: Unassigned | Q18: =IF(F18="Disposable",1,0) -> 0 | R18: =IF(SUMPRODUCT(--ISNUMBER(SEARCH('Spam Rules'!$A$22:$A$35,K18)))>0,1,0) -> 0 | S18: =IF(AND(F18="Free",G18=""),1,0) -> 0 | T18: =IF(LEN(TRIM(K18))<15,1,0) -> 0 | U18: =IF(COUNTIF($E$2:$E$801,E18)>1,1,0) -> 0 | V18: =Q18*'Spam Rules'!$H$6+R18*'Spam Rules'!$H$7+S18*'Spam Rules'!$H$8+T18*'Spam Rules'!$H$9+U18*'Spam Rules'!$H$10 -> 0 | W18: =IF(V18>='Spam Rules'!$B$3,"Likely Spam","Genuine") -> Genuine | X18: =IFERROR(INDEX('Scoring Model'!$B$5:$B$11,MATCH(C18,'Scoring Model'!$A$5:$A$11,0)),0) -> 25 | Y18: =IFERROR(INDEX('Scoring Model'!$E$5:$E$7,MATCH(F18,'Scoring Model'!$D$5:$D$7,0)),0) -> 20 | Z18: =IFERROR(INDEX('Scoring Model'!$H$5:$H$13,MATCH(J18,'Scoring Model'!$G$5:$G$13,0)),0) -> 15 | AA18: =IF(L18>='Scoring Model'!$B$14,'Scoring Model'!$B$15,IF(L18>='Scoring Model'!$B$16,'Scoring Model'!$B$17,0)) -> 15 | AB18: =IF(SUMPRODUCT(--ISNUMBER(SEARCH('Scoring Model'!$D$16:$D$25,K18)))>0,'Scoring Model'!$B$18,0) -> 15 | AC18: =IF(SUMPRODUCT(--ISNUMBER(SEARCH('Scoring Model'!$G$16:$G$23,K18)))>0,'Scoring Model'!$B$19,0) -> 0 | AD18: =IF(W18="Likely Spam","",SUM(X18:AC18)) -> 90 | AE18: =IF(W18="Likely Spam","Spam",IF(AD18>='Scoring Model'!$B$21,"Hot",IF(AD18>='Scoring Model'!$B$22,"Warm","Nurture"))) -> Hot | AF18: =IF(W18="Likely Spam","Flagged by spam rules",TRIM(IF(X18>=20,"Strong source. ","")&IF(Y18>0,"Company email. ","")&IF(Z18>=15,"High-value product. ","")&IF(AA18>='Scoring Model'!$B$15,"High engagement. ","")&IF(AB18>0,"Buying intent in message. ","")&IF(AC18<0,"Negative intent in message. ",""))) -> Strong source. Company email. High-value product. High engagement. Buying intent in message. | AG18: =IF(W18="Likely Spam","",1/(1+EXP(-('Conversion Model'!$B$5+IFERROR(INDEX('Conversion Model'!$B$8:$B$14,MATCH(C18,'Conversion Model'!$A$8:$A$14,0)),0)+IFERROR(INDEX('Conversion Model'!$E$8:$E$9,MATCH(F18,'Conversion Model'!$D$8:$D$9,0)),0)+IFERROR(INDEX('Conversion Model'!$H$8:$H$12,MATCH(IF(LEFT(J18,8)="Payments","Payments",IF(LEFT(J18,7)="Lending","Lending",J18)),'Conversion Model'!$G$8:$G$12,0)),0)+MIN(L18,15)*'Conversion Model'!$B$17+IF(SUMPRODUCT(--ISNUMBER(SEARCH('Scoring Model'!$D$16:$D$25,K18)))>0,'Conversion Model'!$B$18,0)+IF(SUMPRODUCT(--ISNUMBER(SEARCH('Scoring Model'!$G$16:$G$23,K18)))>0,'Conversion Model'!$B$19,0))))) -> 0.99900919 | AH18: =IF(OR(O18="Qualified",O18="Won",O18="Lost"),1,IF(O18="Unqualified",0,""))
A19: L-0018 | B19: 45939.928 | C19: Docs Signup | D19: Lucas Garcia | E19: lucas96@letterdrop.example | F19: Free | I19: India | J19: KYC Verification | K19: test | L19: 1 | M19: 36.5 | N19: Neha | Q19: =IF(F19="Disposable",1,0) -> 0 | R19: =IF(SUMPRODUCT(--ISNUMBER(SEARCH('Spam Rules'!$A$22:$A$35,K19)))>0,1,0) -> 0 | S19: =IF(AND(F19="Free",G19=""),1,0) -> 1 | T19: =IF(LEN(TRIM(K19))<15,1,0) -> 1 | U19: =IF(COUNTIF($E$2:$E$801,E19)>1,1,0) -> 1 | V19: =Q19*'Spam Rules'!$H$6+R19*'Spam Rules'!$H$7+S19*'Spam Rules'!$H$8+T19*'Spam Rules'!$H$9+U19*'Spam Rules'!$H$10 -> 1 | W19: =IF(V19>='Spam Rules'!$B$3,"Likely Spam","Genuine") -> Likely Spam | X19: =IFERROR(INDEX('Scoring Model'!$B$5:$B$11,MATCH(C19,'Scoring Model'!$A$5:$A$11,0)),0) -> 5 | Y19: =IFERROR(INDEX('Scoring Model'!$E$5:$E$7,MATCH(F19,'Scoring Model'!$D$5:$D$7,0)),0) -> 0 | Z19: =IFERROR(INDEX('Scoring Model'!$H$5:$H$13,MATCH(J19,'Scoring Model'!$G$5:$G$13,0)),0) -> 5 | AA19: =IF(L19>='Scoring Model'!$B$14,'Scoring Model'!$B$15,IF(L19>='Scoring Model'!$B$16,'Scoring Model'!$B$17,0)) -> 0 | AB19: =IF(SUMPRODUCT(--ISNUMBER(SEARCH('Scoring Model'!$D$16:$D$25,K19)))>0,'Scoring Model'!$B$18,0) -> 0 | AC19: =IF(SUMPRODUCT(--ISNUMBER(SEARCH('Scoring Model'!$G$16:$G$23,K19)))>0,'Scoring Model'!$B$19,0) -> 0 | AD19: =IF(W19="Likely Spam","",SUM(X19:AC19)) | AE19: =IF(W19="Likely Spam","Spam",IF(AD19>='Scoring Model'!$B$21,"Hot",IF(AD19>='Scoring Model'!$B$22,"Warm","Nurture"))) -> Spam | AF19: =IF(W19="Likely Spam","Flagged by spam rules",TRIM(IF(X19>=20,"Strong source. ","")&IF(Y19>0,"Company email. ","")&IF(Z19>=15,"High-value product. ","")&IF(AA19>='Scoring Model'!$B$15,"High engagement. ","")&IF(AB19>0,"Buying intent in message. ","")&IF(AC19<0,"Negative intent in message. ",""))) -> Flagged by spam rules | AG19: =IF(W19="Likely Spam","",1/(1+EXP(-('Conversion Model'!$B$5+IFERROR(INDEX('Conversion Model'!$B$8:$B$14,MATCH(C19,'Conversion Model'!$A$8:$A$14,0)),0)+IFERROR(INDEX('Conversion Model'!$E$8:$E$9,MATCH(F19,'Conversion Model'!$D$8:$D$9,0)),0)+IFERROR(INDEX('Conversion Model'!$H$8:$H$12,MATCH(IF(LEFT(J19,8)="Payments","Payments",IF(LEFT(J19,7)="Lending","Lending",J19)),'Conversion Model'!$G$8:$G$12,0)),0)+MIN(L19,15)*'Conversion Model'!$B$17+IF(SUMPRODUCT(--ISNUMBER(SEARCH('Scoring Model'!$D$16:$D$25,K19)))>0,'Conversion Model'!$B$18,0)+IF(SUMPRODUCT(--ISNUMBER(SEARCH('Scoring Model'!$G$16:$G$23,K19)))>0,'Conversion Model'!$B$19,0))))) | AH19: =IF(OR(O19="Qualified",O19="Won",O19="Lost"),1,IF(O19="Unqualified",0,""))
A20: L-0019 | B20: 45940.322 | C20: Event | D20: Mei Novak | E20: mei.novak@juniperholtsystems.example | F20: Company | G20: Juniperholt Systems | H20: https://juniperholtsystems.example | I20: Switzerland | J20: Payments - Card Issuing | K20: We are launching a BNPL product and need a managed card issuing setup with go-live in Q4. | L20: 12 | M20: 5.9 | N20: Rahul | Q20: =IF(F20="Disposable",1,0) -> 0 | R20: =IF(SUMPRODUCT(--ISNUMBER(SEARCH('Spam Rules'!$A$22:$A$35,K20)))>0,1,0) -> 0 | S20: =IF(AND(F20="Free",G20=""),1,0) -> 0 | T20: =IF(LEN(TRIM(K20))<15,1,0) -> 0 | U20: =IF(COUNTIF($E$2:$E$801,E20)>1,1,0) -> 0 | V20: =Q20*'Spam Rules'!$H$6+R20*'Spam Rules'!$H$7+S20*'Spam Rules'!$H$8+T20*'Spam Rules'!$H$9+U20*'Spam Rules'!$H$10 -> 0 | W20: =IF(V20>='Spam Rules'!$B$3,"Likely Spam","Genuine") -> Genuine | X20: =IFERROR(INDEX('Scoring Model'!$B$5:$B$11,MATCH(C20,'Scoring Model'!$A$5:$A$11,0)),0) -> 15 | Y20: =IFERROR(INDEX('Scoring Model'!$E$5:$E$7,MATCH(F20,'Scoring Model'!$D$5:$D$7,0)),0) -> 20 | Z20: =IFERROR(INDEX('Scoring Model'!$H$5:$H$13,MATCH(J20,'Scoring Model'!$G$5:$G$13,0)),0) -> 15 | AA20: =IF(L20>='Scoring Model'!$B$14,'Scoring Model'!$B$15,IF(L20>='Scoring Model'!$B$16,'Scoring Model'!$B$17,0)) -> 15 | AB20: =IF(SUMPRODUCT(--ISNUMBER(SEARCH('Scoring Model'!$D$16:$D$25,K20)))>0,'Scoring Model'!$B$18,0) -> 15 | AC20: =IF(SUMPRODUCT(--ISNUMBER(SEARCH('Scoring Model'!$G$16:$G$23,K20)))>0,'Scoring Model'!$B$19,0) -> 0 | AD20: =IF(W20="Likely Spam","",SUM(X20:AC20)) -> 80 | AE20: =IF(W20="Likely Spam","Spam",IF(AD20>='Scoring Model'!$B$21,"Hot",IF(AD20>='Scoring Model'!$B$22,"Warm","Nurture"))) -> Hot | AF20: =IF(W20="Likely Spam","Flagged by spam rules",TRIM(IF(X20>=20,"Strong source. ","")&IF(Y20>0,"Company email. ","")&IF(Z20>=15,"High-value product. ","")&IF(AA20>='Scoring Model'!$B$15,"High engagement. ","")&IF(AB20>0,"Buying intent in message. ","")&IF(AC20<0,"Negative intent in message. ",""))) -> Company email. High-value product. High engagement. Buying intent in message. | AG20: =IF(W20="Likely Spam","",1/(1+EXP(-('Conversion Model'!$B$5+IFERROR(INDEX('Conversion Model'!$B$8:$B$14,MATCH(C20,'Conversion Model'!$A$8:$A$14,0)),0)+IFERROR(INDEX('Conversion Model'!$E$8:$E$9,MATCH(F20,'Conversion Model'!$D$8:$D$9,0)),0)+IFERROR(INDEX('Conversion Model'!$H$8:$H$12,MATCH(IF(LEFT(J20,8)="Payments","Payments",IF(LEFT(J20,7)="Lending","Lending",J20)),'Conversion Model'!$G$8:$G$12,0)),0)+MIN(L20,15)*'Conversion Model'!$B$17+IF(SUMPRODUCT(--ISNUMBER(SEARCH('Scoring Model'!$D$16:$D$25,K20)))>0,'Conversion Model'!$B$18,0)+IF(SUMPRODUCT(--ISNUMBER(SEARCH('Scoring Model'!$G$16:$G$23,K20)))>0,'Conversion Model'!$B$19,0))))) -> 0.99839014 | AH20: =IF(OR(O20="Qualified",O20="Won",O20="Lost"),1,IF(O20="Unqualified",0,""))
A21: L-0020 | B21: 45940.399 | C21: LinkedIn ABM | D21: Noah Lee | E21: noah.lee@plumeridgesystems.example | F21: Company | G21: Plumeridge Systems | H21: https://plumeridgesystems.example | I21: Germany | J21: Banking Data API | K21: Evaluating card issuing providers for our BNPL app. Can we get a demo and a cost comparison? | L21: 5 | M21: 33.6 | N21: Vikram | O21: Won | P21: 96000 | Q21: =IF(F21="Disposable",1,0) -> 0 | R21: =IF(SUMPRODUCT(--ISNUMBER(SEARCH('Spam Rules'!$A$22:$A$35,K21)))>0,1,0) -> 0 | S21: =IF(AND(F21="Free",G21=""),1,0) -> 0 | T21: =IF(LEN(TRIM(K21))<15,1,0) -> 0 | U21: =IF(COUNTIF($E$2:$E$801,E21)>1,1,0) -> 0 | V21: =Q21*'Spam Rules'!$H$6+R21*'Spam Rules'!$H$7+S21*'Spam Rules'!$H$8+T21*'Spam Rules'!$H$9+U21*'Spam Rules'!$H$10 -> 0 | W21: =IF(V21>='Spam Rules'!$B$3,"Likely Spam","Genuine") -> Genuine | X21: =IFERROR(INDEX('Scoring Model'!$B$5:$B$11,MATCH(C21,'Scoring Model'!$A$5:$A$11,0)),0) -> 20 | Y21: =IFERROR(INDEX('Scoring Model'!$E$5:$E$7,MATCH(F21,'Scoring Model'!$D$5:$D$7,0)),0) -> 20 | Z21: =IFERROR(INDEX('Scoring Model'!$H$5:$H$13,MATCH(J21,'Scoring Model'!$G$5:$G$13,0)),0) -> 5 | AA21: =IF(L21>='Scoring Model'!$B$14,'Scoring Model'!$B$15,IF(L21>='Scoring Model'!$B$16,'Scoring Model'!$B$17,0)) -> 8 | AB21: =IF(SUMPRODUCT(--ISNUMBER(SEARCH('Scoring Model'!$D$16:$D$25,K21)))>0,'Scoring Model'!$B$18,0) -> 15 | AC21: =IF(SUMPRODUCT(--ISNUMBER(SEARCH('Scoring Model'!$G$16:$G$23,K21)))>0,'Scoring Model'!$B$19,0) -> 0 | AD21: =IF(W21="Likely Spam","",SUM(X21:AC21)) -> 68 | AE21: =IF(W21="Likely Spam","Spam",IF(AD21>='Scoring Model'!$B$21,"Hot",IF(AD21>='Scoring Model'!$B$22,"Warm","Nurture"))) -> Warm | AF21: =IF(W21="Likely Spam","Flagged by spam rules",TRIM(IF(X21>=20,"Strong source. ","")&IF(Y21>0,"Company email. ","")&IF(Z21>=15,"High-value product. ","")&IF(AA21>='Scoring Model'!$B$15,"High engagement. ","")&IF(AB21>0,"Buying intent in message. ","")&IF(AC21<0,"Negative intent in message. ",""))) -> Strong source. Company email. Buying intent in message. | AG21: =IF(W21="Likely Spam","",1/(1+EXP(-('Conversion Model'!$B$5+IFERROR(INDEX('Conversion Model'!$B$8:$B$14,MATCH(C21,'Conversion Model'!$A$8:$A$14,0)),0)+IFERROR(INDEX('Conversion Model'!$E$8:$E$9,MATCH(F21,'Conversion Model'!$D$8:$D$9,0)),0)+IFERROR(INDEX('Conversion Model'!$H$8:$H$12,MATCH(IF(LEFT(J21,8)="Payments","Payments",IF(LEFT(J21,7)="Lending","Lending",J21)),'Conversion Model'!$G$8:$G$12,0)),0)+MIN(L21,15)*'Conversion Model'!$B$17+IF(SUMPRODUCT(--ISNUMBER(SEARCH('Scoring Model'!$D$16:$D$25,K21)))>0,'Conversion Model'!$B$18,0)+IF(SUMPRODUCT(--ISNUMBER(SEARCH('Scoring Model'!$G$16:$G$23,K21)))>0,'Conversion Model'!$B$19,0))))) -> 0.8610454 | AH21: =IF(OR(O21="Qualified",O21="Won",O21="Lost"),1,IF(O21="Unqualified",0,"")) -> 1
A22: L-0021 | B22: 45940.549 | C22: Pricing Page Form | D22: Zara Kim | E22: zara.kim@plumeridgebank.example | F22: Company | G22: Plumeridge Bank | H22: https://plumeridgebank.example | I22: Nigeria | J22: Banking Data API | K22: Migrating from another provider for our card program, need a quote this month. | L22: 10 | M22: 6.8 | N22: Vikram | Q22: =IF(F22="Disposable",1,0) -> 0 | R22: =IF(SUMPRODUCT(--ISNUMBER(SEARCH('Spam Rules'!$A$22:$A$35,K22)))>0,1,0) -> 0 | S22: =IF(AND(F22="Free",G22=""),1,0) -> 0 | T22: =IF(LEN(TRIM(K22))<15,1,0) -> 0 | U22: =IF(COUNTIF($E$2:$E$801,E22)>1,1,0) -> 0 | V22: =Q22*'Spam Rules'!$H$6+R22*'Spam Rules'!$H$7+S22*'Spam Rules'!$H$8+T22*'Spam Rules'!$H$9+U22*'Spam Rules'!$H$10 -> 0 | W22: =IF(V22>='Spam Rules'!$B$3,"Likely Spam","Genuine") -> Genuine | X22: =IFERROR(INDEX('Scoring Model'!$B$5:$B$11,MATCH(C22,'Scoring Model'!$A$5:$A$11,0)),0) -> 25 | Y22: =IFERROR(INDEX('Scoring Model'!$E$5:$E$7,MATCH(F22,'Scoring Model'!$D$5:$D$7,0)),0) -> 20 | Z22: =IFERROR(INDEX('Scoring Model'!$H$5:$H$13,MATCH(J22,'Scoring Model'!$G$5:$G$13,0)),0) -> 5 | AA22: =IF(L22>='Scoring Model'!$B$14,'Scoring Model'!$B$15,IF(L22>='Scoring Model'!$B$16,'Scoring Model'!$B$17,0)) -> 15 | AB22: =IF(SUMPRODUCT(--ISNUMBER(SEARCH('Scoring Model'!$D$16:$D$25,K22)))>0,'Scoring Model'!$B$18,0) -> 15 | AC22: =IF(SUMPRODUCT(--ISNUMBER(SEARCH('Scoring Model'!$G$16:$G$23,K22)))>0,'Scoring Model'!$B$19,0) -> 0 | AD22: =IF(W22="Likely Spam","",SUM(X22:AC22)) -> 80 | AE22: =IF(W22="Likely Spam","Spam",IF(AD22>='Scoring Model'!$B$21,"Hot",IF(AD22>='Scoring Model'!$B$22,"Warm","Nurture"))) -> Hot | AF22: =IF(W22="Likely Spam","Flagged by spam rules",TRIM(IF(X22>=20,"Strong source. ","")&IF(Y22>0,"Company email. ","")&IF(Z22>=15,"High-value product. ","")&IF(AA22>='Scoring Model'!$B$15,"High engagement. ","")&IF(AB22>0,"Buying intent in message. ","")&IF(AC22<0,"Negative intent in message. ",""))) -> Strong source. Company email. High engagement. Buying intent in message. | AG22: =IF(W22="Likely Spam","",1/(1+EXP(-('Conversion Model'!$B$5+IFERROR(INDEX('Conversion Model'!$B$8:$B$14,MATCH(C22,'Conversion Model'!$A$8:$A$14,0)),0)+IFERROR(INDEX('Conversion Model'!$E$8:$E$9,MATCH(F22,'Conversion Model'!$D$8:$D$9,0)),0)+IFERROR(INDEX('Conversion Model'!$H$8:$H$12,MATCH(IF(LEFT(J22,8)="Payments","Payments",IF(LEFT(J22,7)="Lending","Lending",J22)),'Conversion Model'!$G$8:$G$12,0)),0)+MIN(L22,15)*'Conversion Model'!$B$17+IF(SUMPRODUCT(--ISNUMBER(SEARCH('Scoring Model'!$D$16:$D$25,K22)))>0,'Conversion Model'!$B$18,0)+IF(SUMPRODUCT(--ISNUMBER(SEARCH('Scoring Model'!$G$16:$G$23,K22)))>0,'Conversion Model'!$B$19,0))))) -> 0.99582726 | AH22: =IF(OR(O22="Qualified",O22="Won",O22="Lost"),1,IF(O22="Unqualified",0,""))
